<?xml version="1.0"?>
<robot name="omni_3wd_robot">
  <!-- Base Link -->
  <link name="base_link">
    <visual>
      <geometry>
        <cylinder radius="0.152" length="0.019"/>
      </geometry>
      <material name="yellow">
        <color rgba="1 0.84 0 1"/>
      </material>
    </visual>
    <collision>
      <geometry>
        <cylinder radius="0.152" length="0.019"/>
      </geometry>
    </collision>
    <inertial>
      <mass value="5.0"/>
      <origin xyz="0 0 0"/>
      <inertia ixx="0.1" ixy="0.0" ixz="0.0" iyy="0.1" iyz="0.0" izz="0.1"/>
    </inertial>
  </link>

  <!-- Omni Wheels -->
  <link name="wheel_1">
    <visual>
      <geometry>
        <cylinder radius="0.05" length="0.038"/>
      </geometry>
      <material name="black">
        <color rgba="0.1 0.1 0.1 1"/>
      </material>
    </visual>
  </link>

  <link name="wheel_2">
    <visual>
      <geometry>
        <cylinder radius="0.05" length="0.038"/>
      </geometry>
      <material name="black">
        <color rgba="0.1 0.1 0.1 1"/>
      </material>
    </visual>
  </link>

  <link name="wheel_3">
    <visual>
      <geometry>
        <cylinder radius="0.05" length="0.038"/>
      </geometry>
      <material name="black">
        <color rgba="0.1 0.1 0.1 1"/>
      </material>
    </visual>
  </link>

  <!-- Wheel Joints -->
  <joint name="wheel_joint_1" type="continuous">
    <parent link="base_link"/>
    <child link="wheel_1"/>
    <origin xyz="0.13 0 0" rpy="0 1.5708 0"/>
    <axis xyz="0 0 1"/>
  </joint>

  <joint name="wheel_joint_2" type="continuous">
    <parent link="base_link"/>
    <child link="wheel_2"/>
    <origin xyz="-0.065 0.1126 0" rpy="0 1.5708 2.0944"/>
    <axis xyz="0 0 1"/>
  </joint>

  <joint name="wheel_joint_3" type="continuous">
    <parent link="base_link"/>
    <child link="wheel_3"/>
    <origin xyz="-0.065 -0.1126 0" rpy="0 1.5708 -2.0944"/>
    <axis xyz="0 0 1"/>
  </joint>

  <!-- Ultrasonic Sensor (simplified) -->
  <link name="ultrasonic">
    <visual>
      <geometry>
        <box size="0.04 0.02 0.02"/>
      </geometry>
      <material name="gray">
        <color rgba="0.5 0.5 0.5 1"/>
      </material>
    </visual>
  </link>

  <joint name="ultrasonic_joint" type="fixed">
    <parent link="base_link"/>
    <child link="ultrasonic"/>
    <origin xyz="0.15 0 0.05" rpy="0 0 0"/>
  </joint>
</robot>
